<?xml version="1.0"?>
<robot xmlns:xacro="http://www.ros.org/wiki/xacro">
  <!-- middle of the hand -->
  <xacro:macro name="palm" params="parent *origin">

    <!-- Joint entre wrist et palm -->
    <joint name="wrist_horn_joint" type="fixed">
      <parent link="${parent}"/>
      <child link="horn_2_link"/>
      <xacro:insert_block name="origin"/>
    </joint>

    <!-- Servo link -->
    <link name="horn_2_link">
      <visual>
        <geometry>
          <mesh filename="package://hand_description/meshes/servo_circle_horn.stl" scale="0.001 0.001 0.001"/>
        </geometry>
        <material name="white"/>
        <origin xyz="0 0 0" rpy="0 0 0"/>
      </visual>
      <collision>
          <geometry>
            <mesh filename="package://hand_description/meshes/servo_circle_horn.stl" scale="0.001 0.001 0.001"/>
        </geometry>
        <origin xyz="0 0 0" rpy="0 0 0"/>
      </collision>
      <xacro:cylinder_inertia mass="0.1" radius="0.02" length="0.04"/>
    </link>

    <!-- Color Gazebo for servo -->
    <gazebo reference="horn_2_link">
      <material>Gazebo/White</material>
    </gazebo>

    <!-- Joint entre servo et horn (revolute pour rotation)-->
    <joint name="servo_horn_2_joint" type="revolute">
      <parent link="horn_2_link"/>
      <child link="servo_2_link"/>
      <origin xyz="0 0 0" rpy="0 0 0"/>
      <axis xyz="0 0 1"/>
      <limit effort="10.0" lower="${-70 * pi / 180}" upper="${50 * pi / 180}" velocity="0.3"/>
    </joint>

    <!-- Servo link -->
    <link name="servo_2_link">
      <visual>
        <geometry>
          <mesh filename="package://hand_description/meshes/Servo_Hitec_HS_645MG.stl" scale="0.001 0.001 0.001"/>
        </geometry>
        <material name="black"/>
        <origin xyz="0.01 0 0.045" rpy="${180 * pi / 180} 0 ${180 * pi / 180}"/>
      </visual>
      <collision>
        <geometry>
          <mesh filename="package://hand_description/meshes/Servo_Hitec_HS_645MG.stl" scale="0.001 0.001 0.001"/>
        </geometry>
        <origin xyz="0 0 0" rpy="0 0 0"/>
      </collision>
      <xacro:cylinder_inertia mass="0.1" radius="0.02" length="0.04"/>
    </link>

    <!-- Joint entre palm et servo -->
    <joint name="palm_servo_joint" type="fixed">
      <parent link="servo_2_link"/>
      <child link="palm_link"/>
      <origin xyz="0 0 0" rpy="${90 * pi / 180} 0 0"/>
    </joint>

    <!-- middle base left -->
    <link name="palm_link">
      <visual>
        <geometry>
          <mesh filename="package://hand_description/meshes/palm.stl" scale="0.001 0.001 0.001"/>
        </geometry>
        <material name="white"/>
        <origin xyz="-0.022 0.018 0.004" rpy="${90 * pi / 180} ${-153 * pi / 180} ${95.5 * pi / 180}"/>
      </visual>
      <collision>
        <geometry>
          <mesh filename="package://hand_description/meshes/palm.stl" scale="0.001 0.001 0.001"/>
        </geometry>
        <origin xyz="0 0 0" rpy="0 0 0"/>
      </collision>
      <xacro:cylinder_inertia mass="0.5" radius="0.08" length="0.25"/>
    </link>
    
    <!-- Joint entre palm et servo -->
    <joint name="palm_sg90_index_joint" type="fixed">
      <parent link="palm_link"/>
      <child link="sg90_index_link"/>
      <origin xyz="0.08 0.002 0.014" rpy="${170 * pi / 180} ${0 * pi / 180} ${-100 * pi / 180}"/>
    </joint>

    <!-- middle base left -->
    <link name="sg90_index_link">
      <visual>
        <geometry>
          <mesh filename="package://hand_description/meshes/SG90.stl" scale="0.001 0.001 0.001"/>
        </geometry>
        <material name="black"/>
        <origin xyz="-0.0025 -0.001 0" rpy="${-3 * pi / 180} ${10 * pi / 180} ${2 * pi / 180}"/>
      </visual>
      <collision>
        <geometry>
          <mesh filename="package://hand_description/meshes/SG90.stl" scale="0.001 0.001 0.001"/>
        </geometry>
        <origin xyz="0 0 0" rpy="0 0 0"/>
      </collision>
      <xacro:cylinder_inertia mass="0.5" radius="0.08" length="0.25"/>
    </link>
    

    <!-- Joint entre palm et servo -->
    <joint name="sg90_arm_index_joint" type="revolute">
      <parent link="sg90_index_link"/>
      <child link="sg90_arm_index_link"/>
      <origin xyz="0.0028 0.006 0.03" rpy="${-3 * pi / 180} ${10 * pi / 180} ${2 * pi / 180}"/>
      <axis xyz="0 0 1"/>
      <limit effort="10.0" lower="${20 * pi / 180}" upper="${-40 * pi / 180}" velocity="0.3"/>
    </joint>

    <!-- middle base left -->
    <link name="sg90_arm_index_link">
      <visual>
        <geometry>
          <mesh filename="package://hand_description/meshes/SG90_arm.stl" scale="0.001 0.001 0.001"/>
        </geometry>
        <material name="orange"/>
        <origin xyz="0.0067 0.0003 0" rpy="${180 * pi / 180} ${0 * pi / 180} ${90 * pi / 180}"/>
      </visual>
      <collision>
        <geometry>
          <mesh filename="package://hand_description/meshes/SG90_arm.stl" scale="0.001 0.001 0.001"/>
        </geometry>
        <origin xyz="0 0 0" rpy="0 0 0"/>
      </collision>
      <xacro:cylinder_inertia mass="0.5" radius="0.08" length="0.25"/>
    </link>

    <!-- Joint entre palm et servo -->
    <joint name="arm_steering_index_joint" type="revolute">
      <parent link="sg90_arm_index_link"/>
      <child link="steering_index_link"/>
      <origin xyz="0.01 0.0 0.0" rpy="${0 * pi / 180} ${0 * pi / 180} ${-90 * pi / 180}"/>
      <axis xyz="0 0 1"/>
      <limit effort="10.0" lower="${30 * pi / 180}" upper="${-20 * pi / 180}" velocity="0.3"/>
      <mimic joint="sg90_arm_index_joint" multiplier="-1.1" offset="${10 * pi / 180}"/>
    </joint>

    <!-- middle base left -->
    <link name="steering_index_link">
      <visual>
        <geometry>
          <mesh filename="package://hand_description/meshes/steeringlink_end_v2.stl" scale="0.001 0.001 0.001"/>
        </geometry>
        <material name="blue"/>
        <origin xyz="0.003 0 0" rpy="${0 * pi / 180} ${0 * pi / 180} ${0 * pi / 180}"/>
      </visual>
      <collision>
        <geometry>
          <mesh filename="package://hand_description/meshes/steeringlink_end_v2.stl" scale="0.001 0.001 0.001"/>
        </geometry>
        <origin xyz="0 0 0" rpy="0 0 0"/>
      </collision>
      <xacro:cylinder_inertia mass="0.5" radius="0.08" length="0.25"/>
    </link>

    <!-- Joint entre palm et servo -->
    <joint name="steering_rod_index_joint" type="fixed">
      <parent link="steering_index_link"/>
      <child link="rod_index_link"/>
      <origin xyz="0.009 0.0 0.002" rpy="${0 * pi / 180} ${90 * pi / 180} ${0 * pi / 180}"/>
    </joint>

    <!-- middle base left -->
    <link name="rod_index_link">
      <visual>
        <geometry>
          <cylinder length="0.018" radius="0.0009"/>
        </geometry>
        <material name="gray"/>
        <origin xyz="0.0 0 0.009" rpy="${0 * pi / 180} ${0 * pi / 180} ${0 * pi / 180}"/>
      </visual>
      <collision>
        <geometry>
            <cylinder length="0.018" radius="0.0009"/>
        </geometry>
        <origin xyz="0 0 0" rpy="0 0 0"/>
      </collision>
      <xacro:cylinder_inertia mass="0.5" radius="0.08" length="0.25"/>
    </link>

    <!-- Joint entre palm et servo -->
    <joint name="steering_rod_end_index_joint" type="fixed">
      <parent link="rod_index_link"/>
      <child link="steering_end_index_link"/>
      <origin xyz="0.0 0.0 0.018" rpy="${-90 * pi / 180} ${90 * pi / 180} ${0 * pi / 180}"/>
    </joint>

    <!-- middle base left -->
    <link name="steering_end_index_link">
      <visual>
        <geometry>
          <mesh filename="package://hand_description/meshes/steeringlink_end_v2.stl" scale="0.001 0.001 0.001"/>
        </geometry>
        <material name="blue"/>
        <origin xyz="0.0 0 -0.002" rpy="${0 * pi / 180} ${0 * pi / 180} ${0 * pi / 180}"/>
      </visual>
      <collision>
        <geometry>
          <mesh filename="package://hand_description/meshes/steeringlink_end_v2.stl" scale="0.001 0.001 0.001"/>
        </geometry>
        <origin xyz="0 0 0" rpy="0 0 0"/>
      </collision>
      <xacro:cylinder_inertia mass="0.5" radius="0.08" length="0.25"/>
    </link>

    <!-- Joint entre palm et servo -->
    <joint name="palm_sg90_middle_joint" type="fixed">
      <parent link="palm_link"/>
      <child link="sg90_middle_link"/>
      <origin xyz="0.08 0.026 0.004" rpy="${180 * pi / 180} ${5 * pi / 180} ${-95 * pi / 180}"/>
    </joint>

    <!-- middle base left -->
    <link name="sg90_middle_link">
      <visual>
        <geometry>
          <mesh filename="package://hand_description/meshes/SG90.stl" scale="0.001 0.001 0.001"/>
        </geometry>
        <material name="black"/>
        <origin xyz="-0.0025 -0.001 0" rpy="${-3 * pi / 180} ${10 * pi / 180} ${2 * pi / 180}"/>
      </visual>
      <collision>
        <geometry>
          <mesh filename="package://hand_description/meshes/SG90.stl" scale="0.001 0.001 0.001"/>
        </geometry>
        <origin xyz="0 0 0" rpy="0 0 0"/>
      </collision>
      <xacro:cylinder_inertia mass="0.5" radius="0.08" length="0.25"/>
    </link>
    

    <!-- Joint entre palm et servo -->
    <joint name="sg90_arm_middle_joint" type="revolute">
      <parent link="sg90_middle_link"/>
      <child link="sg90_arm_middle_link"/>
      <origin xyz="0.0028 0.006 0.03" rpy="${-3 * pi / 180} ${10 * pi / 180} ${2 * pi / 180}"/>
      <axis xyz="0 0 1"/>
      <limit effort="10.0" lower="${20 * pi / 180}" upper="${-40 * pi / 180}" velocity="0.3"/>
    </joint>

    <!-- middle base left -->
    <link name="sg90_arm_middle_link">
      <visual>
        <geometry>
          <mesh filename="package://hand_description/meshes/SG90_arm.stl" scale="0.001 0.001 0.001"/>
        </geometry>
        <material name="orange"/>
        <origin xyz="0.0067 0.0003 0" rpy="${180 * pi / 180} ${0 * pi / 180} ${90 * pi / 180}"/>
      </visual>
      <collision>
        <geometry>
          <mesh filename="package://hand_description/meshes/SG90_arm.stl" scale="0.001 0.001 0.001"/>
        </geometry>
        <origin xyz="0 0 0" rpy="0 0 0"/>
      </collision>
      <xacro:cylinder_inertia mass="0.5" radius="0.08" length="0.25"/>
    </link>

    <!-- Joint entre palm et servo -->
    <joint name="arm_steering_middle_joint" type="revolute">
      <parent link="sg90_arm_middle_link"/>
      <child link="steering_middle_link"/>
      <origin xyz="0.01 0.0 0.0" rpy="${0 * pi / 180} ${0 * pi / 180} ${-90 * pi / 180}"/>
      <axis xyz="0 0 1"/>
      <limit effort="10.0" lower="${25 * pi / 180}" upper="${0 * pi / 180}" velocity="0.3"/>
      <mimic joint="sg90_arm_middle_joint" multiplier="-1" offset="${20 * pi / 180}"/>
    </joint>

    <!-- middle base left -->
    <link name="steering_middle_link">
      <visual>
        <geometry>
          <mesh filename="package://hand_description/meshes/steeringlink_end_v2.stl" scale="0.001 0.001 0.001"/>
        </geometry>
        <material name="blue"/>
        <origin xyz="0.003 0 0" rpy="${0 * pi / 180} ${0 * pi / 180} ${0 * pi / 180}"/>
      </visual>
      <collision>
        <geometry>
          <mesh filename="package://hand_description/meshes/steeringlink_end_v2.stl" scale="0.001 0.001 0.001"/>
        </geometry>
        <origin xyz="0 0 0" rpy="0 0 0"/>
      </collision>
      <xacro:cylinder_inertia mass="0.5" radius="0.08" length="0.25"/>
    </link>

    <!-- Joint entre palm et servo -->
    <joint name="steering_rod_middle_joint" type="fixed">
      <parent link="steering_middle_link"/>
      <child link="rod_middle_link"/>
      <origin xyz="0.009 0.0 0.002" rpy="${0 * pi / 180} ${90 * pi / 180} ${0 * pi / 180}"/>
    </joint>

    <!-- middle base left -->
    <link name="rod_middle_link">
      <visual>
        <geometry>
          <cylinder length="0.02" radius="0.0009"/>
        </geometry>
        <material name="gray"/>
        <origin xyz="0.0 0 0.01" rpy="${0 * pi / 180} ${0 * pi / 180} ${0 * pi / 180}"/>
      </visual>
      <collision>
        <geometry>
            <cylinder length="0.02" radius="0.0009"/>
        </geometry>
        <origin xyz="0 0 0" rpy="0 0 0"/>
      </collision>
      <xacro:cylinder_inertia mass="0.5" radius="0.08" length="0.25"/>
    </link>

    <!-- Joint entre palm et servo -->
    <joint name="steering_rod_end_middle_joint" type="fixed">
      <parent link="rod_middle_link"/>
      <child link="steering_end_middle_link"/>
      <origin xyz="0.0 0.0 0.02" rpy="${-90 * pi / 180} ${90 * pi / 180} ${0 * pi / 180}"/>
    </joint>

    <!-- middle base left -->
    <link name="steering_end_middle_link">
      <visual>
        <geometry>
          <mesh filename="package://hand_description/meshes/steeringlink_end_v2.stl" scale="0.001 0.001 0.001"/>
        </geometry>
        <material name="blue"/>
        <origin xyz="0.0 0 -0.002" rpy="${0 * pi / 180} ${0 * pi / 180} ${0 * pi / 180}"/>
      </visual>
      <collision>
        <geometry>
          <mesh filename="package://hand_description/meshes/steeringlink_end_v2.stl" scale="0.001 0.001 0.001"/>
        </geometry>
        <origin xyz="0 0 0" rpy="0 0 0"/>
      </collision>
      <xacro:cylinder_inertia mass="0.5" radius="0.08" length="0.25"/>
    </link>

    <!-- Joint entre palm et servo -->
    <joint name="palm_sg90_ring_joint" type="fixed">
      <parent link="palm_link"/>
      <child link="sg90_ring_link"/>
      <origin xyz="0.079 0.054 0.001" rpy="${180 * pi / 180} ${10 * pi / 180} ${-87 * pi / 180}"/>
    </joint>

    <!-- middle base left -->
    <link name="sg90_ring_link">
      <visual>
        <geometry>
          <mesh filename="package://hand_description/meshes/SG90.stl" scale="0.001 0.001 0.001"/>
        </geometry>
        <material name="black"/>
        <origin xyz="-0.0025 -0.001 0" rpy="${-3 * pi / 180} ${10 * pi / 180} ${2 * pi / 180}"/>
      </visual>
      <collision>
        <geometry>
          <mesh filename="package://hand_description/meshes/SG90.stl" scale="0.001 0.001 0.001"/>
        </geometry>
        <origin xyz="0 0 0" rpy="0 0 0"/>
      </collision>
      <xacro:cylinder_inertia mass="0.5" radius="0.08" length="0.25"/>
    </link>
    

    <!-- Joint entre palm et servo -->
    <joint name="sg90_arm_ring_joint" type="revolute">
      <parent link="sg90_ring_link"/>
      <child link="sg90_arm_ring_link"/>
      <origin xyz="0.0028 0.006 0.03" rpy="${-3 * pi / 180} ${10 * pi / 180} ${2 * pi / 180}"/>
      <axis xyz="0 0 1"/>
      <limit effort="10.0" lower="${20 * pi / 180}" upper="${-40 * pi / 180}" velocity="0.3"/>
    </joint>

    <!-- middle base left -->
    <link name="sg90_arm_ring_link">
      <visual>
        <geometry>
          <mesh filename="package://hand_description/meshes/SG90_arm.stl" scale="0.001 0.001 0.001"/>
        </geometry>
        <material name="orange"/>
        <origin xyz="0.0067 0.0003 0" rpy="${180 * pi / 180} ${0 * pi / 180} ${90 * pi / 180}"/>
      </visual>
      <collision>
        <geometry>
          <mesh filename="package://hand_description/meshes/SG90_arm.stl" scale="0.001 0.001 0.001"/>
        </geometry>
        <origin xyz="0 0 0" rpy="0 0 0"/>
      </collision>
      <xacro:cylinder_inertia mass="0.5" radius="0.08" length="0.25"/>
    </link>

    <!-- Joint entre palm et servo -->
    <joint name="arm_steering_ring_joint" type="revolute">
      <parent link="sg90_arm_ring_link"/>
      <child link="steering_ring_link"/>
      <origin xyz="0.01 0.0 0.0" rpy="${0 * pi / 180} ${0 * pi / 180} ${-90 * pi / 180}"/>
      <axis xyz="0 0 1"/>
      <limit effort="10.0" lower="${25 * pi / 180}" upper="${0 * pi / 180}" velocity="0.3"/>
      <mimic joint="sg90_arm_ring_joint" multiplier="-1" offset="${20 * pi / 180}"/>
    </joint>

    <!-- middle base left -->
    <link name="steering_ring_link">
      <visual>
        <geometry>
          <mesh filename="package://hand_description/meshes/steeringlink_end_v2.stl" scale="0.001 0.001 0.001"/>
        </geometry>
        <material name="blue"/>
        <origin xyz="0.003 0 0" rpy="${0 * pi / 180} ${0 * pi / 180} ${0 * pi / 180}"/>
      </visual>
      <collision>
        <geometry>
          <mesh filename="package://hand_description/meshes/steeringlink_end_v2.stl" scale="0.001 0.001 0.001"/>
        </geometry>
        <origin xyz="0 0 0" rpy="0 0 0"/>
      </collision>
      <xacro:cylinder_inertia mass="0.5" radius="0.08" length="0.25"/>
    </link>

    <!-- Joint entre palm et servo -->
    <joint name="steering_rod_ring_joint" type="fixed">
      <parent link="steering_ring_link"/>
      <child link="rod_ring_link"/>
      <origin xyz="0.009 0.0 0.002" rpy="${0 * pi / 180} ${90 * pi / 180} ${0 * pi / 180}"/>
    </joint>

    <!-- middle base left -->
    <link name="rod_ring_link">
      <visual>
        <geometry>
          <cylinder length="0.02" radius="0.0009"/>
        </geometry>
        <material name="gray"/>
        <origin xyz="0.0 0 0.01" rpy="${0 * pi / 180} ${0 * pi / 180} ${0 * pi / 180}"/>
      </visual>
      <collision>
        <geometry>
            <cylinder length="0.02" radius="0.0009"/>
        </geometry>
        <origin xyz="0 0 0" rpy="0 0 0"/>
      </collision>
      <xacro:cylinder_inertia mass="0.5" radius="0.08" length="0.25"/>
    </link>

    <!-- Joint entre palm et servo -->
    <joint name="steering_rod_end_ring_joint" type="fixed">
      <parent link="rod_ring_link"/>
      <child link="steering_end_ring_link"/>
      <origin xyz="0.0 0.0 0.02" rpy="${-90 * pi / 180} ${90 * pi / 180} ${0 * pi / 180}"/>
    </joint>

    <!-- middle base left -->
    <link name="steering_end_ring_link">
      <visual>
        <geometry>
          <mesh filename="package://hand_description/meshes/steeringlink_end_v2.stl" scale="0.001 0.001 0.001"/>
        </geometry>
        <material name="blue"/>
        <origin xyz="0.0 0 -0.002" rpy="${0 * pi / 180} ${0 * pi / 180} ${0 * pi / 180}"/>
      </visual>
      <collision>
        <geometry>
          <mesh filename="package://hand_description/meshes/steeringlink_end_v2.stl" scale="0.001 0.001 0.001"/>
        </geometry>
        <origin xyz="0 0 0" rpy="0 0 0"/>
      </collision>
      <xacro:cylinder_inertia mass="0.5" radius="0.08" length="0.25"/>
    </link>

    <!-- Joint entre palm et servo -->
    <joint name="palm_sg90_pinky_joint" type="fixed">
      <parent link="palm_link"/>
      <child link="sg90_pinky_link"/>
      <origin xyz="0.046 0.045 0.004" rpy="${180 * pi / 180} ${10 * pi / 180} ${-178 * pi / 180}"/>
    </joint>

    <!-- middle base left -->
    <link name="sg90_pinky_link">
      <visual>
        <geometry>
          <mesh filename="package://hand_description/meshes/SG90.stl" scale="0.001 0.001 0.001"/>
        </geometry>
        <material name="black"/>
        <origin xyz="-0.0025 -0.001 0" rpy="${-3 * pi / 180} ${10 * pi / 180} ${2 * pi / 180}"/>
      </visual>
      <collision>
        <geometry>
          <mesh filename="package://hand_description/meshes/SG90.stl" scale="0.001 0.001 0.001"/>
        </geometry>
        <origin xyz="0 0 0" rpy="0 0 0"/>
      </collision>
      <xacro:cylinder_inertia mass="0.5" radius="0.08" length="0.25"/>
    </link>
    

    <!-- Joint entre palm et servo -->
    <joint name="sg90_arm_pinky_joint" type="revolute">
      <parent link="sg90_pinky_link"/>
      <child link="sg90_arm_pinky_link"/>
      <origin xyz="0.0028 0.006 0.03" rpy="${-3 * pi / 180} ${10 * pi / 180} ${92 * pi / 180}"/>
      <axis xyz="0 0 1"/>
      <limit effort="10.0" lower="${20 * pi / 180}" upper="${-10 * pi / 180}" velocity="0.3"/>
    </joint>

    <!-- middle base left -->
    <link name="sg90_arm_pinky_link">
      <visual>
        <geometry>
          <mesh filename="package://hand_description/meshes/SG90_arm.stl" scale="0.001 0.001 0.001"/>
        </geometry>
        <material name="orange"/>
        <origin xyz="0.0067 0.0003 0" rpy="${180 * pi / 180} ${0 * pi / 180} ${90 * pi / 180}"/>
      </visual>
      <collision>
        <geometry>
          <mesh filename="package://hand_description/meshes/SG90_arm.stl" scale="0.001 0.001 0.001"/>
        </geometry>
        <origin xyz="0 0 0" rpy="0 0 0"/>
      </collision>
      <xacro:cylinder_inertia mass="0.5" radius="0.08" length="0.25"/>
    </link>

    <!-- Joint entre palm et servo -->
    <joint name="palm_sg90_thumb_joint" type="fixed">
      <parent link="palm_link"/>
      <child link="sg90_thumb_link"/>
      <origin xyz="0.051 0.015 0.007" rpy="${170 * pi / 180} ${10 * pi / 180} ${2 * pi / 180}"/>
    </joint>

    <!-- middle base left -->
    <link name="sg90_thumb_link">
      <visual>
        <geometry>
          <mesh filename="package://hand_description/meshes/SG90.stl" scale="0.001 0.001 0.001"/>
        </geometry>
        <material name="black"/>
        <origin xyz="-0.0025 -0.001 0" rpy="${-3 * pi / 180} ${10 * pi / 180} ${2 * pi / 180}"/>
      </visual>
      <collision>
        <geometry>
          <mesh filename="package://hand_description/meshes/SG90.stl" scale="0.001 0.001 0.001"/>
        </geometry>
        <origin xyz="0 0 0" rpy="0 0 0"/>
      </collision>
      <xacro:cylinder_inertia mass="0.5" radius="0.08" length="0.25"/>
    </link>
    

    <!-- Joint entre palm et servo -->
    <joint name="sg90_arm_thumb_joint" type="revolute">
      <parent link="sg90_thumb_link"/>
      <child link="sg90_arm_thumb_link"/>
      <origin xyz="0.0028 0.006 0.03" rpy="${-3 * pi / 180} ${10 * pi / 180} ${92 * pi / 180}"/>
      <axis xyz="0 0 1"/>
      <limit effort="10.0" lower="${0 * pi / 180}" upper="${90 * pi / 180}" velocity="0.3"/>
    </joint>

    <!-- middle base left -->
    <link name="sg90_arm_thumb_link">
      <visual>
        <geometry>
          <mesh filename="package://hand_description/meshes/SG90_arm.stl" scale="0.001 0.001 0.001"/>
        </geometry>
        <material name="orange"/>
        <origin xyz="0.0067 0.0003 0" rpy="${180 * pi / 180} ${0 * pi / 180} ${90 * pi / 180}"/>
      </visual>
      <collision>
        <geometry>
          <mesh filename="package://hand_description/meshes/SG90_arm.stl" scale="0.001 0.001 0.001"/>
        </geometry>
        <origin xyz="0 0 0" rpy="0 0 0"/>
      </collision>
      <xacro:cylinder_inertia mass="0.5" radius="0.08" length="0.25"/>
    </link>


  </xacro:macro>
</robot>